import os
import sys
import traceback
import discord
from discord.ext import commands
import asyncio

class MyBot(commands.Bot):
    def __init__(self):
        intents = discord.Intents.default()
        intents.members = True
        intents.message_content = True
        super().__init__(command_prefix="!", intents=intents, help_command=None)

    async def setup_hook(self):
        for filename in os.listdir("./cogs"):
            if filename.endswith(".py"):
                ext = f"cogs.{filename[:-3]}"
                try:
                    await self.load_extension(ext)
                    print(f"‚úÖ Loaded cog: {ext}")
                except Exception as e:
                    print(f"‚ùå Failed to load {ext}: {e}")

    async def on_ready(self):
        print(f"üöÄ Logged in as {self.user} (ID: {self.user.id})")
        print("üîå Loaded cogs:")
        for i, name in enumerate(self.cogs, start=1):
            print(f"  {i}. {name}")

    async def on_command_error(self, ctx: commands.Context, error: commands.CommandError):
        # Unwrap errors from command invocation
        if isinstance(error, commands.CommandInvokeError):
            original = error.original
        else:
            original = error

        # Handle common command errors
        if isinstance(original, commands.CommandNotFound):
            return  # ignore unknown commands
        elif isinstance(original, commands.MissingRequiredArgument):
            await ctx.send(f"‚ùó Missing argument: `{original.param.name}`")
        elif isinstance(original, commands.BadArgument):
            await ctx.send("‚ùó Bad argument provided.")
        elif isinstance(original, commands.MissingPermissions):
            await ctx.send("‚ùå You don't have permissions for that command.")
        elif isinstance(original, commands.BotMissingPermissions):
            await ctx.send("‚ùå I lack the required permissions to run that command.")
        elif isinstance(original, commands.CommandOnCooldown):
            await ctx.send(f"‚è≥ This command is on cooldown. Try again in {original.retry_after:.2f}s.")
        else:
            # Log unexpected errors
            print(f"Ignoring exception in command {ctx.command}:", file=sys.stderr)
            traceback.print_exception(type(original), original, original.__traceback__, file=sys.stderr)
            await ctx.send("‚ö†Ô∏è An unexpected error occurred. Check logs for details.")

async def main():
    bot = MyBot()
    print("üî• Starting bot...")
    async with bot:
        await bot.start("TOKEN_PASTE")

if __name__ == "__main__":
    asyncio.run(main())
